Error handling in Python is a fundamental concept that allows your programs to gracefully manage unexpected situations and continue running without crashing. Instead of letting an error completely halt your script, you can "catch" the error and decide how to react.

### What are Errors and Exceptions?

In Python, there are generally two types of problems that can occur:

1.  **Syntax Errors:** These are errors in the structure of your code that Python detects *before* your program even runs. Examples include missing colons, incorrect indentation, or misspelled keywords. You fix these by correcting your code.

    ```python
    # Example of a SyntaxError
    if True
        print("Hello") # SyntaxError: expected ':'
    ```

2.  **Exceptions (Runtime Errors):** These errors occur *during* the execution of your program. Even if your code is syntactically correct, something unexpected might happen that prevents the program from continuing normally. Python "raises" an exception, which you can then "handle."

    Common built-in exceptions include:

      * `ZeroDivisionError`: Attempting to divide by zero.
      * `ValueError`: A function receives an argument of the correct type but an inappropriate value (e.g., `int("abc")`).
      * `TypeError`: An operation or function is applied to an object of an inappropriate type (e.g., trying to add a number and a string: `5 + "hello"`).
      * `FileNotFoundError`: Trying to open a file that doesn't exist.
      * `IndexError`: Trying to access an index that is out of bounds for a list or tuple.
      * `KeyError`: Trying to access a non-existent key in a dictionary.
      * `NameError`: Trying to use a variable that hasn't been defined.

### The `try-except-else-finally` Block

Python's primary mechanism for error handling is the `try-except` block, which can be extended with `else` and `finally` clauses.

**Basic Structure:**

```python
try:
    # Code that might raise an exception
    # (This code is "tried" first)
except ExceptionType1:
    # Code to execute if ExceptionType1 occurs in the try block
except ExceptionType2:
    # Code to execute if ExceptionType2 occurs
except:
    # Catch-all for any other exceptions (use with caution!)
else:
    # Code to execute IF NO EXCEPTION occurred in the try block
finally:
    # Code to execute ALWAYS, regardless of whether an exception occurred or not
    # (Useful for cleanup actions)
```

Let's break down each part with examples:

-----

### Examples and Real-Time Scenarios

#### Scenario 1: Handling Invalid User Input (`ValueError`)

Imagine you're building a simple calculator that takes two numbers from the user and divides them. Users might enter non-numeric input.

**Without Error Handling:**

```python
# Without error handling
num1_str = input("Enter the first number: ")
num2_str = input("Enter the second number: ")

num1 = int(num1_str) # What if user enters "abc"?
num2 = int(num2_str) # What if user enters "xyz"?

result = num1 / num2 # What if num2 is 0?
print(f"The result is: {result}")
```

If the user types "hello" for the first number, the program crashes with a `ValueError`. If they type "5" and "0", it crashes with a `ZeroDivisionError`.

**With Error Handling (`try-except` for specific errors):**

```python
def safe_divide():
    try:
        num1_str = input("Enter the first number: ")
        num2_str = input("Enter the second number: ")

        num1 = int(num1_str)
        num2 = int(num2_str)

        result = num1 / num2
        print(f"The result is: {result}")

    except ValueError:
        print("Error: Invalid input. Please enter valid numbers.")
    except ZeroDivisionError:
        print("Error: Cannot divide by zero!")
    except Exception as e: # Catch any other unexpected errors
        print(f"An unexpected error occurred: {e}")

print("--- Simple Calculator ---")
safe_divide()
print("--- Program Finished ---")

# --- Example Runs ---
# Run 1: User enters "hello"
# Enter the first number: hello
# Error: Invalid input. Please enter valid numbers.
# --- Program Finished ---

# Run 2: User enters 10 and 0
# Enter the first number: 10
# Enter the second number: 0
# Error: Cannot divide by zero!
# --- Program Finished ---

# Run 3: User enters 10 and 2
# Enter the first number: 10
# Enter the second number: 2
# The result is: 5.0
# --- Program Finished ---
```

**Explanation:**

  * The `try` block contains the code that *might* cause an error.
  * If a `ValueError` occurs (e.g., `int("hello")`), Python jumps directly to the `except ValueError:` block, prints the specific error message, and the program continues.
  * If a `ZeroDivisionError` occurs, it jumps to that `except` block.
  * The generic `except Exception as e:` block acts as a fallback for any other unexpected errors, printing the error details. This is good for debugging but for production, you want to be as specific as possible.

#### Scenario 2: File Operations (`FileNotFoundError`, `PermissionError`, `IOError`)

When working with files, many things can go wrong: the file might not exist, you might not have permission to read/write it, or there could be general I/O issues.

**Real-time Scenario:** A program that reads configuration from a file.

```python
def read_config(filename):
    file = None # Initialize file handle
    try:
        file = open(filename, 'r') # Try to open the file for reading
        content = file.read()
        print(f"File content:\n{content}")
    except FileNotFoundError:
        print(f"Error: The file '{filename}' was not found. Please check the path.")
    except PermissionError:
        print(f"Error: You don't have permission to access '{filename}'.")
    except IOError as e: # Catch other I/O related errors
        print(f"An I/O error occurred with '{filename}': {e}")
    except Exception as e:
        print(f"An unexpected error occurred: {e}")
    finally:
        # This block always executes, useful for closing resources
        if file: # Check if file was successfully opened before trying to close
            file.close()
            print(f"File '{filename}' closed.")

# --- Example Runs ---
print("\n--- Reading existing file ---")
# Create a dummy file for demonstration
with open("my_config.txt", "w") as f:
    f.write("setting1=value1\nsetting2=value2")
read_config("my_config.txt")

print("\n--- Reading non-existent file ---")
read_config("non_existent.txt")

print("\n--- Simulating a permission error (might need admin rights to truly simulate) ---")
# On Linux/macOS, you can try setting restricted permissions:
# chmod 000 restricted_file.txt
# On Windows, create a file and deny read access for your user.
# For simplicity, let's just show the concept without actual permission change:
# read_config("/root/sensitive_data.txt") # This would likely cause PermissionError on most systems

# A hypothetical scenario for an IOError that isn't FNF or Permission
# (e.g., disk full, corrupted disk) - harder to simulate directly, but catchable
```

**Explanation:**

  * **`try`**: Attempts to open and read the file.
  * **`except FileNotFoundError`**: Catches if the file simply doesn't exist.
  * **`except PermissionError`**: Catches if the operating system denies access.
  * **`except IOError as e`**: `IOError` is a more general I/O error, catching things like disk full errors. We use `as e` to get the specific error message.
  * **`finally`**: The `file.close()` statement is in `finally`. This ensures the file is *always* closed, regardless of whether an error occurred or not. This is crucial for resource management to prevent resource leaks (e.g., files left open).

#### Scenario 3: Database Operations (Connection Issues, Query Errors)

When interacting with databases, network issues or invalid queries are common.

**Real-time Scenario:** A web application trying to fetch user data from a database.

```python
import psycopg2 # Example using PostgreSQL driver (install with `pip install psycopg2-binary`)
from psycopg2 import OperationalError, ProgrammingError

def get_user_data(user_id):
    conn = None
    try:
        # Simulate a database connection (replace with actual connection details)
        conn = psycopg2.connect(
            host="localhost",
            database="mydatabase",
            user="myuser",
            password="mypassword",
            port="5432" # Default PostgreSQL port
        )
        cur = conn.cursor()

        # Simulate a query
        cur.execute(f"SELECT name, email FROM users WHERE id = {user_id}")
        user_data = cur.fetchone()

        if user_data:
            print(f"User found: Name={user_data[0]}, Email={user_data[1]}")
        else:
            print(f"User with ID {user_id} not found.")

    except OperationalError as e:
        print(f"Database Connection Error: {e}. Please check database server and credentials.")
        # In a real app, you might log this, notify an admin, or retry
    except ProgrammingError as e:
        print(f"Database Query Error: {e}. Check your SQL query or table schema.")
        # This could be due to a malformed SQL query or non-existent table/column
    except Exception as e:
        print(f"An unexpected error occurred during database operation: {e}")
    finally:
        if conn:
            conn.close()
            print("Database connection closed.")

# --- Example Runs ---
print("\n--- Fetching existing user (simulated) ---")
# Assuming a user with ID 1 exists in a perfect scenario
get_user_data(1)

print("\n--- Fetching non-existent user ---")
get_user_data(999)

print("\n--- Simulating a connection error (e.g., wrong port, DB not running) ---")
# To trigger this, you might change the port to a wrong one, or stop your local PostgreSQL server.
# For demo purposes, we'll just explain.
# get_user_data(1) # If DB is down, this would hit OperationalError

print("\n--- Simulating a query error (e.g., wrong table name) ---")
def get_user_data_bad_query(user_id):
    conn = None
    try:
        conn = psycopg2.connect(host="localhost", database="mydatabase", user="myuser", password="mypassword")
        cur = conn.cursor()
        cur.execute(f"SELECT name, email FROM non_existent_table WHERE id = {user_id}") # Intentional error
        user_data = cur.fetchone()
        if user_data:
            print(f"User found: Name={user_data[0]}, Email={user_data[1]}")
    except ProgrammingError as e:
        print(f"Database Query Error (Bad Query): {e}")
    except Exception as e:
        print(f"An unexpected error occurred: {e}")
    finally:
        if conn:
            conn.close()
            print("Database connection closed (from bad query attempt).")

# To make this work, you'd need a running PostgreSQL instance and `mydatabase`, `myuser`, `mypassword` set up.
# get_user_data_bad_query(1) # This would likely trigger ProgrammingError
```

**Explanation:**

  * Specific database drivers (like `psycopg2`) define their own exception types (`OperationalError`, `ProgrammingError`, etc.). Catching these allows you to respond precisely.
  * `OperationalError` often relates to connection issues (network, server down).
  * `ProgrammingError` often relates to issues with the SQL query itself (syntax, non-existent tables/columns).
  * `finally` is vital to ensure the database connection is *always* closed, preventing resource exhaustion on the database server.

#### Scenario 4: Network Requests and API Calls (`requests.exceptions.RequestException`, `Timeout`)

Making requests to external APIs or web services is prone to network errors, timeouts, or unexpected responses.

**Real-time Scenario:** A weather application fetching data from a weather API.

```python
import requests

def get_weather(city):
    api_key = "YOUR_API_KEY" # Replace with a real API key for a weather service
    base_url = f"http://api.openweathermap.org/data/2.5/weather?q={city}&appid={api_key}"

    try:
        # Add a timeout to prevent the program from hanging indefinitely
        response = requests.get(base_url, timeout=5)
        response.raise_for_status() # Raises HTTPError for bad responses (4xx or 5xx)

        data = response.json()
        temperature_kelvin = data['main']['temp']
        temperature_celsius = temperature_kelvin - 273.15
        description = data['weather'][0]['description']

        print(f"Weather in {city}:")
        print(f"  Temperature: {temperature_celsius:.2f}°C")
        print(f"  Description: {description.capitalize()}")

    except requests.exceptions.Timeout:
        print(f"Error: Request to weather API timed out for {city}. Please try again later.")
    except requests.exceptions.ConnectionError:
        print(f"Error: Could not connect to the weather API for {city}. Check your internet connection.")
    except requests.exceptions.HTTPError as e:
        print(f"Error: HTTP request failed for {city} - {e.response.status_code} {e.response.reason}")
        if e.response.status_code == 401:
            print("  (Hint: Invalid API Key)")
        elif e.response.status_code == 404:
            print("  (Hint: City not found or API endpoint incorrect)")
    except requests.exceptions.RequestException as e: # Catch any other requests-related error
        print(f"An unexpected request error occurred for {city}: {e}")
    except KeyError:
        print(f"Error: Could not parse weather data for {city}. API response format might have changed.")
    except Exception as e:
        print(f"An unexpected error occurred: {e}")

# --- Example Runs ---
print("\n--- Getting weather for a valid city ---")
get_weather("London") # Replace with a city that works with your API key

print("\n--- Getting weather for a non-existent city ---")
get_weather("NonExistentCity12345")

print("\n--- Simulating network error (e.g., unplug internet) ---")
# You'd have to actually disconnect your internet for this.
# get_weather("Delhi") # This would trigger ConnectionError

print("\n--- Simulating timeout (e.g., very slow server or small timeout) ---")
# You can set `timeout=0.001` for a quicker timeout simulation, but might get ConnectionError too.
# get_weather("Mumbai")
```

**Explanation:**

  * The `requests` library provides its own hierarchy of exceptions.
  * `requests.exceptions.Timeout`: Handles cases where the server doesn't respond within the specified time.
  * `requests.exceptions.ConnectionError`: Handles issues like no internet connection or DNS resolution failures.
  * `requests.exceptions.HTTPError`: Raised by `response.raise_for_status()` for non-200 HTTP responses (e.g., 404 Not Found, 500 Internal Server Error).
  * `requests.exceptions.RequestException`: A base class for all `requests`-related errors, useful as a catch-all for network problems.
  * `KeyError`: Added to handle cases where the API response format changes and expected keys are missing.

#### Scenario 5: Custom Exceptions

Sometimes, built-in exceptions don't fully describe a specific error condition in your application's logic. You can create your own custom exceptions by inheriting from `Exception` (or a more specific built-in exception).

**Real-time Scenario:** A banking system where specific transaction failures need distinct handling.

```python
class InsufficientFundsError(Exception):
    """Raised when an account has insufficient funds for a transaction."""
    def __init__(self, message="Insufficient funds for the transaction."):
        self.message = message
        super().__init__(self.message)

class NegativeAmountError(ValueError): # Inherit from ValueError as it's a value-related issue
    """Raised when a transaction amount is negative."""
    def __init__(self, message="Transaction amount cannot be negative."):
        self.message = message
        super().__init__(self.message)

def make_transaction(account_balance, amount_to_withdraw):
    if amount_to_withdraw < 0:
        raise NegativeAmountError("Withdrawal amount cannot be negative.")
    if amount_to_withdraw > account_balance:
        raise InsufficientFundsError("Not enough money in the account.")
    
    new_balance = account_balance - amount_to_withdraw
    print(f"Transaction successful. New balance: {new_balance}")
    return new_balance

# --- Example Runs ---
initial_balance = 1000

print("\n--- Successful Withdrawal ---")
try:
    make_transaction(initial_balance, 200)
except InsufficientFundsError as e:
    print(f"Transaction failed: {e}")
except NegativeAmountError as e:
    print(f"Transaction failed: {e}")
except Exception as e:
    print(f"An unexpected error occurred: {e}")

print("\n--- Withdrawal with Insufficient Funds ---")
try:
    make_transaction(initial_balance, 1500)
except InsufficientFundsError as e:
    print(f"Transaction failed: {e}")
except NegativeAmountError as e:
    print(f"Transaction failed: {e}")
except Exception as e:
    print(f"An unexpected error occurred: {e}")

print("\n--- Withdrawal with Negative Amount ---")
try:
    make_transaction(initial_balance, -50)
except InsufficientFundsError as e:
    print(f"Transaction failed: {e}")
except NegativeAmountError as e:
    print(f"Transaction failed: {e}")
except Exception as e:
    print(f"An unexpected error occurred: {e}")
```

**Explanation:**

  * We define `InsufficientFundsError` and `NegativeAmountError` to make the error handling more semantic. Instead of just catching a generic `Exception`, we can specifically address banking-related failures.
  * The `raise` statement is used to explicitly trigger these custom exceptions when the conditions are met.
  * The `except` blocks can then catch these specific custom exceptions, allowing for tailored error messages and logic.

### Best Practices for Error Handling:

1.  **Be Specific:** Always try to catch specific exceptions (e.g., `ValueError`, `FileNotFoundError`) rather than a generic `except Exception:`. This makes your code more robust and easier to debug, as you know exactly what kind of error you're handling. A bare `except:` can mask important bugs.
2.  **Keep `try` Blocks Small:** Only put the code that is likely to raise an exception inside the `try` block. This helps in pinpointing the source of the error and keeps your error-handling logic focused.
3.  **Use `finally` for Cleanup:** Always use `finally` for actions that *must* happen, such as closing files, database connections, or releasing network sockets, even if an error occurs.
4.  **Use `else` for Success:** The `else` block is executed only if the `try` block completes without any exceptions. This helps differentiate code that runs normally from error-handling code.
5.  **Log Errors:** In real-world applications, instead of just printing error messages, use Python's `logging` module to record exceptions. This provides a history of issues for debugging and monitoring.
6.  **Avoid Silently Passing Errors:** Don't just use `pass` in an `except` block. If you catch an error, at least log it or provide some user feedback, otherwise, you're masking a potential problem.
7.  **Custom Exceptions:** Define your own custom exception classes when built-in exceptions don't accurately describe the error condition in your application's domain. This improves readability and maintainability.
8.  **Graceful Degradation/User Feedback:** Instead of crashing, aim to handle errors gracefully. This might involve providing meaningful error messages to the user, suggesting alternative actions, or retrying operations where appropriate.

By implementing effective error handling, you make your Python applications more reliable, user-friendly, and easier to maintain in real-world scenarios.
