You're asking for a deeper dive into how to handle specific types of errors in Python, which is a great question because proper error handling makes your code robust and user-friendly.

Let's revisit the `try-except-else-finally` block and then explore how to handle various common error types with practical examples.

### The `try-except-else-finally` Block (Refresher)

This is the core structure for error handling in Python:

```python
try:
    # Code that might raise an exception (the "risky" part)
    # If an exception occurs here, Python jumps to the appropriate 'except' block.
except SpecificErrorType as e:
    # Code to execute if 'SpecificErrorType' occurs.
    # 'e' is an optional variable that holds the exception instance,
    # giving you details about the error.
    print(f"Caught a specific error: {e}")
    # You can log the error, inform the user, try a fallback, etc.
except AnotherErrorType:
    # Code for a different specific error.
except (ErrorTypeA, ErrorTypeB):
    # Catch multiple exception types with one block.
except: # Very general catch-all (use with caution, as it can hide bugs!)
    print("An unknown error occurred!")
else:
    # This block executes ONLY if the code inside the 'try' block
    # runs completely WITHOUT raising any exceptions.
    print("Try block executed successfully!")
finally:
    # This block ALWAYS executes, regardless of whether an exception occurred
    # or not, or if 'try' or 'except' blocks finished.
    # It's ideal for cleanup operations (closing files, releasing resources).
    print("Finally block always runs.")
```

-----

### Handling Specific Error Types with Examples

Let's go through common error types and how to handle them effectively.

#### 1\. `ValueError` (Invalid Data Type or Value)

Raised when an operation or function receives an argument that has the right type but an inappropriate value.

**Scenario:** Converting user input to an integer or float, but the input isn't a valid number.

```python
def get_positive_number():
    while True: # Loop until valid input is received
        try:
            user_input = input("Please enter a positive integer: ")
            number = int(user_input) # Attempt to convert to int

            if number <= 0:
                # If the number is not positive, it's a ValueError conceptually
                # We raise it ourselves to fit our custom logic
                raise ValueError("Number must be positive.")
            
            print(f"You entered: {number}")
            return number # Exit loop and function if successful

        except ValueError as e:
            # Catch specific ValueError (from int() or our custom raise)
            print(f"Invalid input: {e}. Please try again.")
        except Exception as e:
            # Catch any other unexpected errors during input
            print(f"An unexpected error occurred: {e}")

# --- Test Runs ---
print("--- Test get_positive_number ---")
get_positive_number()
# Example interactions:
# Enter a positive integer: abc
# Invalid input: invalid literal for int() with base 10: 'abc'. Please try again.
# Enter a positive integer: 0
# Invalid input: Number must be positive.. Please try again.
# Enter a positive integer: 50
# You entered: 50
```

**Handling Strategy:**

  * Use `try-except` around the conversion or validation logic.
  * Provide clear feedback to the user about what went wrong.
  * Often, you'll loop to prompt for input again until valid data is provided.
  * You can also `raise ValueError` yourself if a valid *type* is given but the *value* is logically incorrect for your application (like a non-positive number when positive is required).

#### 2\. `ZeroDivisionError`

Raised when the second operand of a division or modulo operation is zero.

**Scenario:** Calculating a ratio or average where the denominator could be zero.

```python
def calculate_ratio(numerator, denominator):
    try:
        ratio = numerator / denominator
        print(f"The ratio of {numerator} to {denominator} is: {ratio}")
        return ratio
    except ZeroDivisionError:
        print("Error: Cannot divide by zero. Please provide a non-zero denominator.")
        return None # Indicate failure
    except TypeError: # Good to also catch if input types are wrong
        print("Error: Numerator and denominator must be numbers.")
        return None
    except Exception as e:
        print(f"An unexpected error occurred: {e}")
        return None

# --- Test Runs ---
print("\n--- Test calculate_ratio ---")
calculate_ratio(10, 2)    # Output: The ratio of 10 to 2 is: 5.0
calculate_ratio(5, 0)     # Output: Error: Cannot divide by zero...
calculate_ratio(100, 3)   # Output: The ratio of 100 to 3 is: 33.333...
calculate_ratio("abc", 5) # Output: Error: Numerator and denominator must be numbers.
```

**Handling Strategy:**

  * Explicitly catch `ZeroDivisionError`.
  * Inform the user (or log) that division by zero is not allowed.
  * Consider returning a special value (`None`, `float('inf')`, `float('nan')`) or re-raising a more specific custom exception if appropriate for your application's logic.

#### 3\. `FileNotFoundError` (and other `IOError` types like `PermissionError`)

Raised when an attempt to open a file fails because the file does not exist. `IOError` is a more general base class for input/output errors, including `PermissionError` (when you don't have access rights).

**Scenario:** Reading configuration files, user data, or logging to a file.

```python
def read_and_process_file(filepath):
    file_handle = None # Initialize to None for the finally block
    try:
        file_handle = open(filepath, 'r') # Open file for reading
        content = file_handle.read()
        print(f"Successfully read file '{filepath}':\n{content[:100]}...") # Print first 100 chars
        # Further processing of content here
        return content
    except FileNotFoundError:
        print(f"Error: The file '{filepath}' was not found. Please check the path and filename.")
        return None
    except PermissionError:
        print(f"Error: You do not have sufficient permissions to read '{filepath}'.")
        return None
    except IOError as e: # Catch other I/O errors (e.g., disk full, corrupted file)
        print(f"An I/O error occurred while accessing '{filepath}': {e}")
        return None
    except Exception as e:
        print(f"An unexpected error occurred: {e}")
        return None
    finally:
        # Ensures the file is closed even if an error occurs
        if file_handle: # Only close if it was successfully opened
            file_handle.close()
            print(f"File '{filepath}' has been closed.")

# --- Test Runs ---
print("\n--- Test read_and_process_file ---")

# 1. Create a dummy file for success case
with open("my_settings.txt", "w") as f:
    f.write("API_KEY=abcdef12345\nDEBUG=True\nLOG_LEVEL=INFO")
read_and_process_file("my_settings.txt")

# 2. Test non-existent file
read_and_process_file("non_existent_file.txt")

# 3. Test permission error (requires creating a file with restricted permissions)
# On Linux/macOS: touch restricted.txt && chmod 000 restricted.txt
# read_and_process_file("restricted.txt") # Uncomment to test if you set permissions
# Output might be: Error: You do not have sufficient permissions to read 'restricted.txt'.

# 4. Test with a directory path (often leads to IsADirectoryError, a subclass of OSError)
# This might also fall under IOError/OSError depending on OS/Python version
# read_and_process_file(".")
```

**Handling Strategy:**

  * Catch `FileNotFoundError` specifically to tell the user the file is missing.
  * Catch `PermissionError` if access rights are a concern.
  * Catch `IOError` (or its base `OSError`) for broader system-related file issues.
  * **Crucially, use a `finally` block to ensure that file handles are always closed**, preventing resource leaks. The `with open(...) as ...:` statement is even better as it handles closing automatically.

#### 4\. `IndexError` (List/Tuple Index Out of Range)

Raised when you try to access an index that is outside the bounds of a list or tuple.

**Scenario:** Accessing elements from a list based on user input or a calculated index.

```python
def get_list_element(data_list, index):
    try:
        element = data_list[index]
        print(f"Element at index {index}: {element}")
        return element
    except IndexError:
        print(f"Error: Index {index} is out of range for the list of size {len(data_list)}.")
        return None
    except TypeError: # If data_list is not a sequence
        print("Error: The provided data is not a list or similar sequence.")
        return None
    except Exception as e:
        print(f"An unexpected error occurred: {e}")
        return None

# --- Test Runs ---
print("\n--- Test get_list_element ---")
my_list = ['apple', 'banana', 'cherry', 'date']

get_list_element(my_list, 0) # Output: Element at index 0: apple
get_list_element(my_list, 3) # Output: Element at index 3: date
get_list_element(my_list, 4) # Output: Error: Index 4 is out of range...
get_list_element(my_list, -1) # Output: Element at index -1: date
get_list_element(my_list, 100) # Output: Error: Index 100 is out of range...
get_list_element("hello", 0) # Strings are sequences, so this works
get_list_element(123, 0) # Output: Error: The provided data is not a list or similar sequence.
```

**Handling Strategy:**

  * Catch `IndexError` to handle out-of-bounds access.
  * Inform the user or log the invalid index.
  * If the index is user-provided, you might loop to request valid input.
  * Often, you can avoid `IndexError` by checking `if 0 <= index < len(my_list):` before accessing, especially for validation.

#### 5\. `KeyError` (Dictionary Key Not Found)

Raised when you try to access a dictionary key that doesn't exist.

**Scenario:** Retrieving data from a dictionary where a key might be optional or misspelled.

```python
def get_user_info(user_data, key):
    try:
        value = user_data[key]
        print(f"Value for '{key}': {value}")
        return value
    except KeyError:
        print(f"Error: The key '{key}' was not found in the user data.")
        # Offer alternatives or a default
        if key == "email":
            print("  (Hint: Try 'e-mail' or check capitalization?)")
        return None
    except TypeError: # If user_data is not a dictionary
        print("Error: The provided data is not a dictionary.")
        return None
    except Exception as e:
        print(f"An unexpected error occurred: {e}")
        return None

# --- Test Runs ---
print("\n--- Test get_user_info ---")
profile = {
    "name": "Alice",
    "age": 30,
    "city": "London",
    "email": "alice@example.com"
}

get_user_info(profile, "name")  # Output: Value for 'name': Alice
get_user_info(profile, "country") # Output: Error: The key 'country' was not found...
get_user_info(profile, "email")  # Output: Value for 'email': alice@example.com
get_user_info(profile, "Email")  # Output: Error: The key 'Email' was not found...
get_user_info("not a dict", "name") # Output: Error: The provided data is not a dictionary.
```

**Handling Strategy:**

  * Catch `KeyError` specifically.
  * Provide a helpful message indicating the missing key.
  * **Alternative:** Use the `dict.get(key, default_value)` method if you simply want to provide a default value rather than raise an error (e.g., `value = user_data.get('phone', 'N/A')`). This is often cleaner for optional keys.

#### 6\. `TypeError` (Operation on Incompatible Types)

Raised when an operation or function is applied to an object of an inappropriate type.

**Scenario:** Trying to add a number to a string, or performing a mathematical operation on `None`.

```python
def process_data(value1, value2):
    try:
        # Example of type-sensitive operations
        sum_result = value1 + value2
        print(f"Sum: {sum_result}")

        # Example of calling a method on a potentially wrong type
        print(f"Length of value1: {len(value1)}")

    except TypeError as e:
        print(f"Error: Incompatible types for operation - {e}. Please ensure inputs are of compatible types.")
        return None
    except Exception as e:
        print(f"An unexpected error occurred: {e}")
        return None

# --- Test Runs ---
print("\n--- Test process_data ---")
process_data(10, 20)      # Output: Sum: 30, Length of value1: Error... (TypeError on len(10))
process_data("hello", " world") # Output: Sum: hello world, Length of value1: 5
process_data(10, "world") # Output: Error: Incompatible types for operation... (TypeError on 10 + "world")
process_data(None, 5)     # Output: Error: Incompatible types for operation... (TypeError on None + 5)
```

**Handling Strategy:**

  * Catch `TypeError`.
  * The error message (`e`) often clearly indicates the incompatibility.
  * If you're dealing with external inputs, consider explicit type checking (`isinstance()`) or type conversion *before* attempting the operation, and catch `ValueError` if conversions fail.

#### 7\. `NameError` (Undefined Variable/Function)

Raised when a local or global name is not found. Often indicates a typo or an uninitialized variable.

**Scenario:** Using a variable before it's assigned a value, or calling a function that hasn't been defined.

```python
def demonstrate_name_error():
    try:
        # print(undefined_variable) # This line would cause NameError
        
        # Corrected: define the variable
        defined_variable = 10
        print(f"Defined variable: {defined_variable}")

        # try_to_call_non_existent_function() # This line would cause NameError
        
    except NameError as e:
        print(f"Error: A name (variable or function) was not found - {e}. Check for typos or if it's defined.")
    except Exception as e:
        print(f"An unexpected error occurred: {e}")

# --- Test Run ---
print("\n--- Test demonstrate_name_error ---")
demonstrate_name_error()
# If you uncomment `print(undefined_variable)`, output will be:
# Error: A name (variable or function) was not found - name 'undefined_variable' is not defined.
```

**Handling Strategy:**

  * While you *can* catch `NameError`, it's usually indicative of a programming bug rather than a runtime scenario you'd expect to recover from.
  * It's generally better to fix `NameError` during development by ensuring all variables are initialized and functions are defined before use.
  * However, in very dynamic code where you might be evaluating user-provided expressions, catching it might be necessary.

-----

### General Tips for Robust Error Handling

1.  **Specificity is Key:** Always prioritize catching specific exception types. A bare `except:` clause can catch *any* error, including `SystemExit` or `KeyboardInterrupt`, making it hard to debug or even stop your program.
2.  **Order Matters:** When catching multiple specific exceptions, list the more specific exceptions first, followed by more general ones. If `except ZeroDivisionError` comes after `except Exception`, the `ZeroDivisionError` will never be caught specifically.
3.  **`else` for Success:** Use the `else` block to put code that *should only run if the `try` block succeeds*. This makes your logic clearer.
4.  **`finally` for Cleanup:** Always put resource cleanup code (closing files, database connections, network sockets) in `finally` blocks to guarantee execution. The `with` statement (for files, locks, etc.) is even better as it handles `finally` implicitly.
5.  **Logging, Not Just Printing:** In real applications, use Python's `logging` module to record errors. This helps in debugging issues in deployed applications without affecting the user interface.
6.  **User-Friendly Messages:** Translate technical error messages into something a non-technical user can understand and act upon.
7.  **Don't Swallow Errors:** Avoid empty `except` blocks (`except SomeError: pass`). If you catch an error, you should at least log it or provide some feedback. Silently ignoring errors can lead to subtle and hard-to-find bugs later.
8.  **When to `raise`:**
      * **Custom Errors:** If a situation is an "error" for *your application's logic* but doesn't map to a built-in Python exception, define and raise a custom exception.
      * **Re-raising:** Sometimes you catch an error to log it, but then you want to re-raise it so a higher-level part of your program can also handle it or crash if necessary. Use `raise` inside an `except` block.
        ```python
        try:
            # some code
        except SomeError as e:
            print("An error occurred, but I'm logging it before re-raising.")
            # log.error(e)
            raise # Re-raises the caught exception
        ```

By thoughtfully applying these error handling techniques, you can write Python code that is robust, resilient, and provides a better experience for both users and developers.
